<sdf version='1.7'>
  <model name='tm12'>
    <joint name='world_joint' type='fixed'>
      <pose relative_to='__model__'>0 0 0 0 -0 0</pose>
      <parent>world</parent>
      <child>base</child>
    </joint>
    <link name='base'>
      <pose relative_to='world_joint'>0 0 0 0 -0 0</pose>
      <inertial>
        <pose>0 0 0 0 -0 0</pose>
        <mass>1</mass>
        <inertia>
          <ixx>0.00110833</ixx>
          <ixy>0</ixy>
          <ixz>0</ixz>
          <iyy>0.00110833</iyy>
          <iyz>0</iyz>
          <izz>0.0018</izz>
        </inertia>
      </inertial>
      <collision name='base_fixed_joint_lump__link_0_collision'>
        <pose>0 0 0 0 -0 0</pose>
        <geometry>
          <mesh>
            <scale>1 1 1</scale>
            <uri>model://tm12/meshes/tm12/collision/tm12-base_c.stl</uri>
          </mesh>
        </geometry>
        <surface>
          <contact>
            <ode/>
          </contact>
          <friction>
            <ode/>
          </friction>
        </surface>
      </collision>
      <visual name='base_fixed_joint_lump__link_0_visual'>
        <pose>0 0 0 0 -0 0</pose>
        <geometry>
          <mesh>
            <scale>1 1 1</scale>
            <uri>model://tm12/meshes/tm12/visual/tm12-base.obj</uri>
          </mesh>
        </geometry>
        <material>
          <script>
            <name>Gazebo/Motorway</name>
            <uri>file://media/materials/scripts/gazebo.material</uri>
          </script>
        </material>
      </visual>
      <self_collide>1</self_collide>
    </link>
    <joint name='shoulder_1_joint' type='revolute'>
      <pose relative_to='base'>0 0 0.1652 0 -0 0</pose>
      <parent>base</parent>
      <child>link_1</child>
      <axis>
        <xyz>0 0 1</xyz>
        <limit>
          <lower>-4.71239</lower>
          <upper>4.71239</upper>
          <effort>353</effort>
          <velocity>2.0944</velocity>
        </limit>
        <dynamics>
          <damping>0</damping>
          <friction>0</friction>
          <spring_reference>0</spring_reference>
          <spring_stiffness>0</spring_stiffness>
        </dynamics>
      </axis>
    </joint>
    <link name='link_1'>
      <pose relative_to='shoulder_1_joint'>0 0 0 0 -0 0</pose>
      <inertial>
        <pose>0 0 0 0 -0 0</pose>
        <mass>7.6</mass>
        <inertia>
          <ixx>0.0202893</ixx>
          <ixy>0</ixy>
          <ixz>0</ixz>
          <iyy>0.0202893</iyy>
          <iyz>0</iyz>
          <izz>0.0213963</izz>
        </inertia>
      </inertial>
      <collision name='link_1_collision'>
        <pose>0 0 0 0 -0 0</pose>
        <geometry>
          <mesh>
            <scale>1 1 1</scale>
            <uri>model://tm12/meshes/tm12/collision/tmr_750w_01_c.stl</uri>
          </mesh>
        </geometry>
        <surface>
          <contact>
            <ode/>
          </contact>
          <friction>
            <ode/>
          </friction>
        </surface>
      </collision>
      <visual name='link_1_visual'>
        <pose>0 0 0 0 -0 0</pose>
        <geometry>
          <mesh>
            <scale>1 1 1</scale>
            <uri>model://tm12/meshes/tm12/visual/tmr_750w_01.obj</uri>
          </mesh>
        </geometry>
        <material>
          <script>
            <name>Gazebo/Footway</name>
            <uri>file://media/materials/scripts/gazebo.material</uri>
          </script>
        </material>
      </visual>
      <self_collide>1</self_collide>
    </link>
    <joint name='shoulder_2_joint' type='revolute'>
      <pose relative_to='link_1'>0 0 0 -1.5708 -1.5708 0</pose>
      <parent>link_1</parent>
      <child>link_2</child>
      <axis>
        <xyz>0 0 1</xyz>
        <limit>
          <lower>-3.14159</lower>
          <upper>3.14159</upper>
          <effort>353</effort>
          <velocity>2.0944</velocity>
        </limit>
        <dynamics>
          <damping>0</damping>
          <friction>0</friction>
          <spring_reference>0</spring_reference>
          <spring_stiffness>0</spring_stiffness>
        </dynamics>
      </axis>
    </joint>
    <link name='link_2'>
      <pose relative_to='shoulder_2_joint'>0 0 0 0 -0 0</pose>
      <inertial>
        <pose>0 0 0 0 -0 0</pose>
        <mass>14.0239</mass>
        <inertia>
          <ixx>0.0715057</ixx>
          <ixy>0</ixy>
          <ixz>0</ixz>
          <iyy>1.17588</iyy>
          <iyz>0</iyz>
          <izz>1.20339</izz>
        </inertia>
      </inertial>
      <collision name='link_2_collision'>
        <pose>0 0 0 0 -0 0</pose>
        <geometry>
          <mesh>
            <scale>1 1 1</scale>
            <uri>model://tm12/meshes/tm12/collision/tm12-arm1_c.stl</uri>
          </mesh>
        </geometry>
        <surface>
          <contact>
            <ode/>
          </contact>
          <friction>
            <ode/>
          </friction>
        </surface>
      </collision>
      <visual name='link_2_visual'>
        <pose>0 0 0 0 -0 0</pose>
        <geometry>
          <mesh>
            <scale>1 1 1</scale>
            <uri>model://tm12/meshes/tm12/visual/tm12-arm1.obj</uri>
          </mesh>
        </geometry>
        <material>
          <script>
            <name>Gazebo/Pedestrian</name>
            <uri>file://media/materials/scripts/gazebo.material</uri>
          </script>
        </material>
      </visual>
      <self_collide>1</self_collide>
    </link>
    <joint name='elbow_joint' type='revolute'>
      <pose relative_to='link_2'>0.6361 0 0 0 -0 0</pose>
      <parent>link_2</parent>
      <child>link_3</child>
      <axis>
        <xyz>0 0 1</xyz>
        <limit>
          <lower>-2.89725</lower>
          <upper>2.89725</upper>
          <effort>157</effort>
          <velocity>3.14159</velocity>
        </limit>
        <dynamics>
          <damping>0</damping>
          <friction>0</friction>
          <spring_reference>0</spring_reference>
          <spring_stiffness>0</spring_stiffness>
        </dynamics>
      </axis>
    </joint>
    <link name='link_3'>
      <pose relative_to='elbow_joint'>0 0 0 0 -0 0</pose>
      <inertial>
        <pose>0 0 0 0 -0 0</pose>
        <mass>3.3577</mass>
        <inertia>
          <ixx>0.00975547</ixx>
          <ixy>0</ixy>
          <ixz>0</ixz>
          <iyy>0.163347</iyy>
          <iyz>0</iyz>
          <izz>0.166567</izz>
        </inertia>
      </inertial>
      <collision name='link_3_collision'>
        <pose>0 0 0 0 -0 0</pose>
        <geometry>
          <mesh>
            <scale>1 1 1</scale>
            <uri>model://tm12/meshes/tm12/collision/tm12-arm2_c.stl</uri>
          </mesh>
        </geometry>
        <surface>
          <contact>
            <ode/>
          </contact>
          <friction>
            <ode/>
          </friction>
        </surface>
      </collision>
      <visual name='link_3_visual'>
        <pose>0 0 0 0 -0 0</pose>
        <geometry>
          <mesh>
            <scale>1 1 1</scale>
            <uri>model://tm12/meshes/tm12/visual/tm12-arm2.obj</uri>
          </mesh>
        </geometry>
        <material>
          <script>
            <name>Gazebo/Footway</name>
            <uri>file://media/materials/scripts/gazebo.material</uri>
          </script>
        </material>
      </visual>
      <self_collide>1</self_collide>
    </link>
    <joint name='wrist_1_joint' type='revolute'>
      <pose relative_to='link_3'>0.5579 0 -0.1563 0 -0 1.5708</pose>
      <parent>link_3</parent>
      <child>link_4</child>
      <axis>
        <xyz>0 0 1</xyz>
        <limit>
          <lower>-3.14159</lower>
          <upper>3.14159</upper>
          <effort>54</effort>
          <velocity>3.14159</velocity>
        </limit>
        <dynamics>
          <damping>0</damping>
          <friction>0</friction>
          <spring_reference>0</spring_reference>
          <spring_stiffness>0</spring_stiffness>
        </dynamics>
      </axis>
    </joint>
    <link name='link_4'>
      <pose relative_to='wrist_1_joint'>0 0 0 0 -0 0</pose>
      <inertial>
        <pose>0 0 0 0 -0 0</pose>
        <mass>1.576</mass>
        <inertia>
          <ixx>0.00205841</ixx>
          <ixy>0</ixy>
          <ixz>0</ixz>
          <iyy>0.00256308</iyy>
          <iyz>0</iyz>
          <izz>0.00264321</izz>
        </inertia>
      </inertial>
      <collision name='link_4_collision'>
        <pose>0 0 0 0 -0 0</pose>
        <geometry>
          <mesh>
            <scale>1 1 1</scale>
            <uri>model://tm12/meshes/tm12/collision/tmr_100w_01_c.stl</uri>
          </mesh>
        </geometry>
        <surface>
          <contact>
            <ode/>
          </contact>
          <friction>
            <ode/>
          </friction>
        </surface>
      </collision>
      <visual name='link_4_visual'>
        <pose>0 0 0 0 -0 0</pose>
        <geometry>
          <mesh>
            <scale>1 1 1</scale>
            <uri>model://tm12/meshes/tm12/visual/tmr_100w_01.obj</uri>
          </mesh>
        </geometry>
        <material>
          <script>
            <name>Gazebo/Motorway</name>
            <uri>file://media/materials/scripts/gazebo.material</uri>
          </script>
        </material>
      </visual>
      <self_collide>1</self_collide>
    </link>
    <joint name='wrist_2_joint' type='revolute'>
      <pose relative_to='link_4'>0 -0.106 0 1.5708 -0 0</pose>
      <parent>link_4</parent>
      <child>link_5</child>
      <axis>
        <xyz>0 0 1</xyz>
        <limit>
          <lower>-3.14159</lower>
          <upper>3.14159</upper>
          <effort>54</effort>
          <velocity>3.14159</velocity>
        </limit>
        <dynamics>
          <damping>0</damping>
          <friction>0</friction>
          <spring_reference>0</spring_reference>
          <spring_stiffness>0</spring_stiffness>
        </dynamics>
      </axis>
    </joint>
    <link name='link_5'>
      <pose relative_to='wrist_2_joint'>0 0 0 0 -0 0</pose>
      <inertial>
        <pose>0 0 0 0 -0 0</pose>
        <mass>1.576</mass>
        <inertia>
          <ixx>0.00205841</ixx>
          <ixy>0</ixy>
          <ixz>0</ixz>
          <iyy>0.00256308</iyy>
          <iyz>0</iyz>
          <izz>0.00264321</izz>
        </inertia>
      </inertial>
      <collision name='link_5_collision'>
        <pose>0 0 0 0 -0 0</pose>
        <geometry>
          <mesh>
            <scale>1 1 1</scale>
            <uri>model://tm12/meshes/tm12/collision/tmr_100w_02_c.stl</uri>
          </mesh>
        </geometry>
        <surface>
          <contact>
            <ode/>
          </contact>
          <friction>
            <ode/>
          </friction>
        </surface>
      </collision>
      <visual name='link_5_visual'>
        <pose>0 0 0 0 -0 0</pose>
        <geometry>
          <mesh>
            <scale>1 1 1</scale>
            <uri>model://tm12/meshes/tm12/visual/tmr_100w_02.obj</uri>
          </mesh>
        </geometry>
        <material>
          <script>
            <name>Gazebo/Pedestrian</name>
            <uri>file://media/materials/scripts/gazebo.material</uri>
          </script>
        </material>
      </visual>
      <self_collide>1</self_collide>
    </link>
    <joint name='wrist_3_joint' type='revolute'>
      <pose relative_to='link_5'>0 -0.11315 0 1.5708 -0 0</pose>
      <parent>link_5</parent>
      <child>link_6</child>
      <axis>
        <xyz>0 0 1</xyz>
        <limit>
          <lower>-4.71239</lower>
          <upper>4.71239</upper>
          <effort>54</effort>
          <velocity>3.14159</velocity>
        </limit>
        <dynamics>
          <damping>0</damping>
          <friction>0</friction>
          <spring_reference>0</spring_reference>
          <spring_stiffness>0</spring_stiffness>
        </dynamics>
      </axis>
    </joint>
    <link name='link_6'>
      <pose relative_to='wrist_3_joint'>0 0 0 0 -0 0</pose>
      <inertial>
        <pose>0 0 0 0 -0 0</pose>
        <mass>0.65</mass>
        <inertia>
          <ixx>0.000774544</ixx>
          <ixy>0</ixy>
          <ixz>0</ixz>
          <iyy>0.00138381</iyy>
          <iyz>0</iyz>
          <izz>0.0015595</izz>
        </inertia>
      </inertial>
      <collision name='link_6_collision'>
        <pose>0 0 0 0 -0 0</pose>
        <geometry>
          <mesh>
            <scale>1 1 1</scale>
            <uri>model://tm12/meshes/tm12/collision/tmr_ee_c.stl</uri>
          </mesh>
        </geometry>
        <surface>
          <contact>
            <ode/>
          </contact>
          <friction>
            <ode/>
          </friction>
        </surface>
      </collision>
      <visual name='link_6_visual'>
        <pose>0 0 0 0 -0 0</pose>
        <geometry>
          <mesh>
            <scale>1 1 1</scale>
            <uri>model://tm12/meshes/tm12/visual/tmr_ee.obj</uri>
          </mesh>
        </geometry>
        <material>
          <script>
            <name>Gazebo/DarkGrey</name>
            <uri>file://media/materials/scripts/gazebo.material</uri>
          </script>
        </material>
      </visual>
      <self_collide>1</self_collide>
    </link>
    <static>0</static>
    <plugin name='gazebo_ros_control' filename='libgazebo_ros_control.so'>
      <robotNamespace>/</robotNamespace>
      <robotSimType>gazebo_ros_control/DefaultRobotHWSim</robotSimType>
    </plugin>
  </model>
</sdf>
