<?xml version='1.0' encoding='UTF-8'?>
<robot name="tm5-900">
  <link name="link_0">
    <visual>
      <geometry>
        <mesh filename="package://tmr_description/meshes/tm5-900/visual/tm5_base.obj" />
      </geometry>
    </visual>
    <collision>
      <geometry>
        <mesh filename="package://tmr_description/meshes/tm5-900/collision/tm5_base_c.stl" />
      </geometry>
    </collision>
  </link>
  <joint name="joint_1" type="revolute">
    <parent link="link_0" />
    <child link="link_1" />
    <origin rpy="0.000000 -0.000000 -0.000018" xyz="0.000000 0.000000 0.145100" />
    <axis xyz="0 0 1" />
    <limit effort="100.0" lower="-4.8346" upper="4.8346" velocity="1.0" />
  </joint>
  <link name="link_1">
    <visual>
      <geometry>
        <mesh filename="package://tmr_description/meshes/tm5-900/visual/tmr_400w_01.obj" />
      </geometry>
    </visual>
    <collision>
      <geometry>
        <mesh filename="package://tmr_description/meshes/tm5-900/collision/tmr_400w_01_c.stl" />
      </geometry>
    </collision>
  </link>
  <joint name="joint_2" type="revolute">
    <parent link="link_1" />
    <child link="link_2" />
    <origin rpy="-1.208300 -1.569562 -0.362515" xyz="0.000010 0.000068 0.000000" />
    <axis xyz="0 0 1" />
    <limit effort="100.0" lower="-3.2638" upper="3.2638" velocity="1.0" />
  </joint>
  <link name="link_2">
    <visual>
      <geometry>
        <mesh filename="package://tmr_description/meshes/tm5-900/visual/tm5-900_arm1.obj" />
      </geometry>
    </visual>
    <collision>
      <geometry>
        <mesh filename="package://tmr_description/meshes/tm5-900/collision/tm5-900_arm1_c.stl" />
      </geometry>
    </collision>
  </link>
  <joint name="joint_3" type="revolute">
    <parent link="link_2" />
    <child link="link_3" />
    <origin rpy="0.005376 -0.000593 0.006547" xyz="0.429029 -0.000000 0.000068" />
    <axis xyz="0 0 1" />
    <limit effort="100.0" lower="-2.8274" upper="2.8274" velocity="1.0" />
  </joint>
  <link name="link_3">
    <visual>
      <geometry>
        <mesh filename="package://tmr_description/meshes/tm5-900/visual/tm5-900_arm2.obj" />
      </geometry>
    </visual>
    <collision>
      <geometry>
        <mesh filename="package://tmr_description/meshes/tm5-900/collision/tm5-900_arm2_c.stl" />
      </geometry>
    </collision>
  </link>
  <joint name="joint_4" type="revolute">
    <parent link="link_3" />
    <child link="link_4" />
    <origin rpy="-0.001062 -0.001154 1.571161" xyz="0.411623 0.000141 -0.122132" />
    <axis xyz="0 0 1" />
    <limit effort="10.0" lower="-3.2638" upper="3.2638" velocity="1.0" />
  </joint>
  <link name="link_4">
    <visual>
      <geometry>
        <mesh filename="package://tmr_description/meshes/tm5-900/visual/tmr_100w_01.obj" />
      </geometry>
    </visual>
    <collision>
      <geometry>
        <mesh filename="package://tmr_description/meshes/tm5-900/collision/tmr_100w_01_c.stl" />
      </geometry>
    </collision>
  </link>
  <joint name="joint_5" type="revolute">
    <parent link="link_4" />
    <child link="link_5" />
    <origin rpy="1.571314 -0.001443 0.000362" xyz="-0.000095 -0.106061 -0.000055" />
    <axis xyz="0 0 1" />
    <limit effort="10.0" lower="-3.2638" upper="3.2638" velocity="1.0" />
  </joint>
  <link name="link_5">
    <visual>
      <geometry>
        <mesh filename="package://tmr_description/meshes/tm5-900/visual/tmr_100w_02.obj" />
      </geometry>
    </visual>
    <collision>
      <geometry>
        <mesh filename="package://tmr_description/meshes/tm5-900/collision/tmr_100w_02_c.stl" />
      </geometry>
    </collision>
  </link>
  <joint name="joint_6" type="revolute">
    <parent link="link_5" />
    <child link="link_6" />
    <origin rpy="1.571355 -0.011670 0.001437" xyz="0.000183 -0.114320 -0.000064" />
    <axis xyz="0 0 1" />
    <limit effort="10.0" lower="-4.8346" upper="4.8346" velocity="1.0" />
  </joint>
  <link name="link_6">
    <visual>
      <geometry>
        <mesh filename="package://tmr_description/meshes/tm5-900/visual/tmr_ee.obj" />
      </geometry>
    </visual>
    <collision>
      <geometry>
        <mesh filename="package://tmr_description/meshes/tm5-900/collision/tmr_ee_c.stl" />
      </geometry>
    </collision>
  </link>
  <link name="base" />
  <joint name="base_fixed_joint" type="fixed">
    <parent link="base" />
    <child link="link_0" />
    <origin rpy="0.0 0.0 0.0" xyz="0.0 0.0 0.0" />
  </joint>
  <link name="flange" />
  <joint name="flange_fixed_joint" type="fixed">
    <parent link="link_6" />
    <child link="flange" />
    <origin rpy="0.012173 0.024881 0.000303" xyz="-0.000179 0.000000 0.000000" />
  </joint>
</robot>