<?xml version="1.0" encoding="utf-8" ?>
<!-- =================================================================================== -->
<!-- |    This document was autogenerated by xacro from /home/yhtsai/dev_tmr_ros1/src/techman_robot/tmr_description/xacro/tm5-900.urdf.xacro | -->
<!-- |    EDITING THIS FILE BY HAND IS NOT RECOMMENDED                                 | -->
<!-- =================================================================================== -->
<robot name="tm5-900">
    <gazebo reference="link_1">
        <selfCollide>true</selfCollide>
    </gazebo>
    <gazebo reference="link_2">
        <selfCollide>true</selfCollide>
    </gazebo>
    <gazebo reference="link_3">
        <selfCollide>true</selfCollide>
    </gazebo>
    <gazebo reference="link_4">
        <selfCollide>true</selfCollide>
    </gazebo>
    <gazebo reference="link_5">
        <selfCollide>true</selfCollide>
    </gazebo>
    <gazebo reference="link_6">
        <selfCollide>true</selfCollide>
    </gazebo>
    <gazebo>
        <plugin filename="libgazebo_ros_control.so" name="gazebo_ros_control">
            <robotNamespace>/</robotNamespace>
            <robotSimType>gazebo_ros_control/DefaultRobotHWSim</robotSimType>
        </plugin>
    </gazebo>
    <transmission name="trans_1">
        <type>transmission_interface/SimpleTransmission</type>
        <joint name="joint_1">
            <hardwareInterface>hardware_interface/PositionJointInterface</hardwareInterface>
        </joint>
        <actuator name="motor_1">
            <mechanicalReduction>1</mechanicalReduction>
        </actuator>
    </transmission>
    <transmission name="trans_2">
        <type>transmission_interface/SimpleTransmission</type>
        <joint name="joint_2">
            <hardwareInterface>hardware_interface/PositionJointInterface</hardwareInterface>
        </joint>
        <actuator name="motor_2">
            <mechanicalReduction>1</mechanicalReduction>
        </actuator>
    </transmission>
    <transmission name="trans_3">
        <type>transmission_interface/SimpleTransmission</type>
        <joint name="joint_3">
            <hardwareInterface>hardware_interface/PositionJointInterface</hardwareInterface>
        </joint>
        <actuator name="motor_3">
            <mechanicalReduction>1</mechanicalReduction>
        </actuator>
    </transmission>
    <transmission name="trans_4">
        <type>transmission_interface/SimpleTransmission</type>
        <joint name="joint_4">
            <hardwareInterface>hardware_interface/PositionJointInterface</hardwareInterface>
        </joint>
        <actuator name="motor_4">
            <mechanicalReduction>1</mechanicalReduction>
        </actuator>
    </transmission>
    <transmission name="trans_5">
        <type>transmission_interface/SimpleTransmission</type>
        <joint name="joint_5">
            <hardwareInterface>hardware_interface/PositionJointInterface</hardwareInterface>
        </joint>
        <actuator name="motor_5">
            <mechanicalReduction>1</mechanicalReduction>
        </actuator>
    </transmission>
    <transmission name="trans_6">
        <type>transmission_interface/SimpleTransmission</type>
        <joint name="joint_6">
            <hardwareInterface>hardware_interface/PositionJointInterface</hardwareInterface>
        </joint>
        <actuator name="motor_6">
            <mechanicalReduction>1</mechanicalReduction>
        </actuator>
    </transmission>
    <material name="grey">
        <color rgba="0.5 0.5 0.5 1.0" />
    </material>
    <material name="white">
        <color rgba="0.95 0.95 0.95 1.0" />
    </material>
    <material name="red">
        <color rgba="0.95 0.0 0.0 1.0" />
    </material>
    <material name="orange">
        <color rgba="1.0 0.5 0.0 1.0" />
    </material>
    <material name="yellow">
        <color rgba="1.0 1.0 0.0 1.0" />
    </material>
    <material name="green">
        <color rgba="0.0 1.0 0.0 1.0" />
    </material>
    <material name="blue">
        <color rgba="0.0 0.0 1.0 1.0" />
    </material>
    <material name="indigo">
        <color rgba="0.3 0.3 0.6 1.0" />
    </material>
    <material name="violet">
        <color rgba="0.6 0.0 1.0 1.0" />
    </material>
    <material name="black">
        <color rgba="0.0 0.0 0.0 1.0" />
    </material>
    <!--
LinkDescriptionStart
/-->
    <link name="link_0">
        <visual>
            <geometry>
                <mesh filename="package://tmr_description/meshes/tm5-900/visual/tm5_base.obj" />
            </geometry>
            <material name="none" />
        </visual>
        <collision>
            <geometry>
                <mesh filename="package://tmr_description/meshes/tm5-900/collision/tm5_base_c.stl" />
            </geometry>
        </collision>
        
<inertial>
            <mass value="1.0" />
            <origin rpy="0 0 0" xyz="0 0 0" />
            <inertia ixx="0.00110833289" ixy="0.0" ixz="0.0" iyy="0.00110833289" iyz="0.0" izz="0.0018" />
        </inertial>

    </link>
    <joint name="joint_1" type="revolute">
        <parent link="link_0" />
        <child link="link_1" />
        <origin rpy="0 0 0" xyz="0 0 0.1452" />
        <axis xyz="0 0 1" />
        <!--limit-->
        <limit effort="320.0" lower="-4.71238898038" upper="4.71238898038" velocity="3.14" />
    </joint>
    <link name="link_1">
        <visual>
            <geometry>
                <mesh filename="package://tmr_description/meshes/tm5-900/visual/tmr_400w_01.obj" />
            </geometry>
            <material name="none" />
        </visual>
        <collision>
            <geometry>
                <mesh filename="package://tmr_description/meshes/tm5-900/collision/tmr_400w_01_c.stl" />
            </geometry>
        </collision>
        
<inertial>
            <mass value="4.5" />
            <origin rpy="0 0 0" xyz="0 0 0" />
            <inertia ixx="0.012487495005" ixy="0.0" ixz="0.0" iyy="0.012487495005" iyz="0.0" izz="0.0081" />
        </inertial>

    </link>
    <joint name="joint_2" type="revolute">
        <parent link="link_1" />
        <child link="link_2" />
        <origin rpy="-1.57079632679 -1.57079632679 0" xyz="0 0 0" />
        <axis xyz="0 0 1" />
        <!--limit-->
        <limit effort="320" lower="-3.14159265359" upper="3.14159265359" velocity="3.14" />
    </joint>
    <link name="link_2">
        <visual>
            <geometry>
                <mesh filename="package://tmr_description/meshes/tm5-900/visual/tm5-900_arm1.obj" />
            </geometry>
            <material name="none" />
        </visual>
        <collision>
            <geometry>
                <mesh filename="package://tmr_description/meshes/tm5-900/collision/tm5-900_arm1_c.stl" />
            </geometry>
        </collision>
        
<inertial>
            <mass value="11.0" />
            <origin rpy="0 0 0" xyz="0.2145 0 -0.146" />
            <inertia ixx="0.0198" ixy="0.0" ixz="0.0" iyy="0.178604178558" iyz="0.0" izz="0.178604178558" />
        </inertial>

    </link>
    <joint name="joint_3" type="revolute">
        <parent link="link_2" />
        <child link="link_3" />
        <origin rpy="0 0 0" xyz="0.429 0 0" />
        <axis xyz="0 0 1" />
        <!--limit-->
        <limit effort="320" lower="-3.14159265359" upper="3.14159265359" velocity="3.14" />
    </joint>
    <link name="link_3">
        <visual>
            <geometry>
                <mesh filename="package://tmr_description/meshes/tm5-900/visual/tm5-900_arm2.obj" />
            </geometry>
            <material name="none" />
        </visual>
        <collision>
            <geometry>
                <mesh filename="package://tmr_description/meshes/tm5-900/collision/tm5-900_arm2_c.stl" />
            </geometry>
        </collision>
        
<inertial>
            <mass value="2.5" />
            <origin rpy="0 0 0" xyz="0.20575 0 -0.0163" />
            <inertia ixx="0.00253125" ixy="0.0" ixz="0.0" iyy="0.0365431624661" iyz="0.0" izz="0.0365431624661" />
        </inertial>

    </link>
    <joint name="joint_4" type="revolute">
        <parent link="link_3" />
        <child link="link_4" />
        <origin rpy="0 0 1.57079632679" xyz="0.4115 0 -0.1223" />
        <axis xyz="0 0 1" />
        <!--limit-->
        <limit effort="80" lower="-3.14159265359" upper="3.14159265359" velocity="3.92" />
    </joint>
    <link name="link_4">
        <visual>
            <geometry>
                <mesh filename="package://tmr_description/meshes/tm5-900/visual/tmr_100w_01.obj" />
            </geometry>
            <material name="none" />
        </visual>
        <collision>
            <geometry>
                <mesh filename="package://tmr_description/meshes/tm5-900/collision/tmr_100w_01_c.stl" />
            </geometry>
        </collision>
        
<inertial>
            <mass value="1.45" />
            <origin rpy="0 0 0" xyz="0 0 0" />
            <inertia ixx="0.00247406151038" ixy="0.0" ixz="0.0" iyy="0.001468125" iyz="0.0" izz="0.00247406151038" />
        </inertial>

    </link>
    <joint name="joint_5" type="revolute">
        <parent link="link_4" />
        <child link="link_5" />
        <origin rpy="1.57079632679 0 0" xyz="0 -0.106 0" />
        <axis xyz="0 0 1" />
        <!--limit-->
        <limit effort="80" lower="-3.14159265359" upper="3.14159265359" velocity="3.92" />
    </joint>
    <link name="link_5">
        <visual>
            <geometry>
                <mesh filename="package://tmr_description/meshes/tm5-900/visual/tmr_100w_02.obj" />
            </geometry>
            <material name="none" />
        </visual>
        <collision>
            <geometry>
                <mesh filename="package://tmr_description/meshes/tm5-900/collision/tmr_100w_02_c.stl" />
            </geometry>
        </collision>
        
<inertial>
            <mass value="1.45" />
            <origin rpy="0 0 0" xyz="0 0 0" />
            <inertia ixx="0.00247406151038" ixy="0.0" ixz="0.0" iyy="0.001468125" iyz="0.0" izz="0.00247406151038" />
        </inertial>

    </link>
    <joint name="joint_6" type="revolute">
        <parent link="link_5" />
        <child link="link_6" />
        <origin rpy="1.57079632679 0 0" xyz="0 -0.11315 0" />
        <axis xyz="0 0 1" />
        <!--limit-->
        <limit effort="80" lower="-4.71238898038" upper="4.71238898038" velocity="3.92" />
    </joint>
    <link name="link_6">
        <visual>
            <geometry>
                <mesh filename="package://tmr_description/meshes/tm5-900/visual/tmr_ee.obj" />
            </geometry>
            <material name="none" />
        </visual>
        <collision>
            <geometry>
                <mesh filename="package://tmr_description/meshes/tm5-900/collision/tmr_ee_c.stl" />
            </geometry>
        </collision>
        
<inertial>
            <mass value="0.4" />
            <origin rpy="0 0 0" xyz="0 0 0" />
            <inertia ixx="0.000322499871" ixy="0.0" ixz="0.0" iyy="0.000322499871" iyz="0.0" izz="0.000405" />
        </inertial>

    </link>
    <link name="base" />
    <joint name="base_fixed_joint" type="fixed">
        <parent link="base" />
        <child link="link_0" />
        <origin rpy="0 0 0" xyz="0 0 0" />
    </joint>
    <link name="flange" />
    <joint name="flange_fixed_joint" type="fixed">
        <parent link="link_6" />
        <child link="flange" />
        <origin rpy="0 0 0" xyz="0 0 0" />
    </joint>
    <!--
LinkDescriptionEnd
/-->
<!--
    <link name="world" />
    <joint name="world_joint" type="fixed">
        <parent link="world" />
        <child link="base" />
        <origin rpy="0 0 0" xyz="0 0 0" />
    </joint>
-->
    <transmission name="trans_joint_1">
        <type>transmission_interface/SimpleTransmission</type>
        <joint name="joint_1">
            <hardwareInterface>hardware_interface/EffortJointInterface</hardwareInterface>
        </joint>
        <actuator name="joint_1_motor">
            <hardwareInterface>hardware_interface/EffortJointInterface</hardwareInterface>
            <mechanicalReduction>1</mechanicalReduction>
        </actuator>
    </transmission>
    <transmission name="trans_joint_2">
        <type>transmission_interface/SimpleTransmission</type>
        <joint name="joint_2">
            <hardwareInterface>hardware_interface/EffortJointInterface</hardwareInterface>
        </joint>
        <actuator name="joint_2_motor">
            <hardwareInterface>hardware_interface/EffortJointInterface</hardwareInterface>
            <mechanicalReduction>1</mechanicalReduction>
        </actuator>
    </transmission>
    <transmission name="trans_joint_3">
        <type>transmission_interface/SimpleTransmission</type>
        <joint name="joint_3">
            <hardwareInterface>hardware_interface/EffortJointInterface</hardwareInterface>
        </joint>
        <actuator name="joint_3_motor">
            <hardwareInterface>hardware_interface/EffortJointInterface</hardwareInterface>
            <mechanicalReduction>1</mechanicalReduction>
        </actuator>
    </transmission>
    <transmission name="trans_joint_4">
        <type>transmission_interface/SimpleTransmission</type>
        <joint name="joint_4">
            <hardwareInterface>hardware_interface/EffortJointInterface</hardwareInterface>
        </joint>
        <actuator name="joint_4_motor">
            <hardwareInterface>hardware_interface/EffortJointInterface</hardwareInterface>
            <mechanicalReduction>1</mechanicalReduction>
        </actuator>
    </transmission>
    <transmission name="trans_joint_5">
        <type>transmission_interface/SimpleTransmission</type>
        <joint name="joint_5">
            <hardwareInterface>hardware_interface/EffortJointInterface</hardwareInterface>
        </joint>
        <actuator name="joint_5_motor">
            <hardwareInterface>hardware_interface/EffortJointInterface</hardwareInterface>
            <mechanicalReduction>1</mechanicalReduction>
        </actuator>
    </transmission>
    <transmission name="trans_joint_6">
        <type>transmission_interface/SimpleTransmission</type>
        <joint name="joint_6">
            <hardwareInterface>hardware_interface/EffortJointInterface</hardwareInterface>
        </joint>
        <actuator name="joint_6_motor">
            <hardwareInterface>hardware_interface/EffortJointInterface</hardwareInterface>
            <mechanicalReduction>1</mechanicalReduction>
        </actuator>
    </transmission>
    <gazebo>
        <plugin name="gazebo_ros_control" filename="libgazebo_ros_control.so">
            <robotNamespace>/</robotNamespace>
        </plugin>
    </gazebo>
</robot>

<transmission name="trans_1">
        <type>transmission_interface/SimpleTransmission</type>
        <joint name="joint_1">
            <hardwareInterface>hardware_interface/PositionJointInterface</hardwareInterface>
        </joint>
        <actuator name="motor_1">
            <mechanicalReduction>1</mechanicalReduction>
        </actuator>
    </transmission>
    <transmission name="trans_2">
        <type>transmission_interface/SimpleTransmission</type>
        <joint name="joint_2">
            <hardwareInterface>hardware_interface/PositionJointInterface</hardwareInterface>
        </joint>
        <actuator name="motor_2">
            <mechanicalReduction>1</mechanicalReduction>
        </actuator>
    </transmission>
    <transmission name="trans_3">
        <type>transmission_interface/SimpleTransmission</type>
        <joint name="joint_3">
            <hardwareInterface>hardware_interface/PositionJointInterface</hardwareInterface>
        </joint>
        <actuator name="motor_3">
            <mechanicalReduction>1</mechanicalReduction>
        </actuator>
    </transmission>
    <transmission name="trans_4">
        <type>transmission_interface/SimpleTransmission</type>
        <joint name="joint_4">
            <hardwareInterface>hardware_interface/PositionJointInterface</hardwareInterface>
        </joint>
        <actuator name="motor_4">
            <mechanicalReduction>1</mechanicalReduction>
        </actuator>
    </transmission>
    <transmission name="trans_5">
        <type>transmission_interface/SimpleTransmission</type>
        <joint name="joint_5">
            <hardwareInterface>hardware_interface/PositionJointInterface</hardwareInterface>
        </joint>
        <actuator name="motor_5">
            <mechanicalReduction>1</mechanicalReduction>
        </actuator>
    </transmission>
    <transmission name="trans_6">
        <type>transmission_interface/SimpleTransmission</type>
        <joint name="joint_6">
            <hardwareInterface>hardware_interface/PositionJointInterface</hardwareInterface>
        </joint>
        <actuator name="motor_6">
            <mechanicalReduction>1</mechanicalReduction>
        </actuator>
    </transmission>
    <material name="grey">
        <color rgba="0.5 0.5 0.5 1.0" />
    </material>
    <material name="white">
        <color rgba="0.95 0.95 0.95 1.0" />
    </material>
    <material name="red">
        <color rgba="0.95 0.0 0.0 1.0" />
    </material>
    <material name="orange">
        <color rgba="1.0 0.5 0.0 1.0" />
    </material>
    <material name="yellow">
        <color rgba="1.0 1.0 0.0 1.0" />
    </material>
    <material name="green">
        <color rgba="0.0 1.0 0.0 1.0" />
    </material>
    <material name="blue">
        <color rgba="0.0 0.0 1.0 1.0" />
    </material>
    <material name="indigo">
        <color rgba="0.3 0.3 0.6 1.0" />
    </material>
    <material name="violet">
        <color rgba="0.6 0.0 1.0 1.0" />
    </material>
    <material name="black">
        <color rgba="0.0 0.0 0.0 1.0" />
    </material>
    <!--
LinkDescriptionStart
/-->
    <link name="link_0">
        <visual>
            <geometry>
                <mesh filename="package://tmr_description/meshes/tm5-900/visual/tm5_base.obj" />
            </geometry>
            <material name="none" />
        </visual>
        <collision>
            <geometry>
                <mesh filename="package://tmr_description/meshes/tm5-900/collision/tm5_base_c.stl" />
            </geometry>
        </collision>
        <inertial>
            <mass value="1.0" />
            <origin rpy="0 0 0" xyz="0 0 0" />
            <inertia ixx="0.00110833289" ixy="0.0" ixz="0.0" iyy="0.00110833289" iyz="0.0" izz="0.0018" />
        </inertial>
    </link>
    <joint name="joint_1" type="revolute">
        <parent link="link_0" />
        <child link="link_1" />
        <origin rpy="0 0 0" xyz="0 0 0.1452" />
        <axis xyz="0 0 1" />
        <!--limit-->
        <limit effort="320.0" lower="-4.71238898038" upper="4.71238898038" velocity="3.14" />
    </joint>
    <link name="link_1">
        <visual>
            <geometry>
                <mesh filename="package://tmr_description/meshes/tm5-900/visual/tmr_400w_01.obj" />
            </geometry>
            <material name="none" />
        </visual>
        <collision>
            <geometry>
                <mesh filename="package://tmr_description/meshes/tm5-900/collision/tmr_400w_01_c.stl" />
            </geometry>
        </collision>
        <inertial>
            <mass value="4.5" />
            <origin rpy="0 0 0" xyz="0 0 0" />
            <inertia ixx="0.012487495005" ixy="0.0" ixz="0.0" iyy="0.012487495005" iyz="0.0" izz="0.0081" />
        </inertial>
    </link>
    <joint name="joint_2" type="revolute">
        <parent link="link_1" />
        <child link="link_2" />
        <origin rpy="-1.57079632679 -1.57079632679 0" xyz="0 0 0" />
        <axis xyz="0 0 1" />
        <!--limit-->
        <limit effort="320" lower="-3.14159265359" upper="3.14159265359" velocity="3.14" />
    </joint>
    <link name="link_2">
        <visual>
            <geometry>
                <mesh filename="package://tmr_description/meshes/tm5-900/visual/tm5-900_arm1.obj" />
            </geometry>
            <material name="none" />
        </visual>
        <collision>
            <geometry>
                <mesh filename="package://tmr_description/meshes/tm5-900/collision/tm5-900_arm1_c.stl" />
            </geometry>
        </collision>
        <inertial>
            <mass value="11.0" />
            <origin rpy="0 0 0" xyz="0.2145 0 -0.146" />
            <inertia ixx="0.0198" ixy="0.0" ixz="0.0" iyy="0.178604178558" iyz="0.0" izz="0.178604178558" />
        </inertial>
    </link>
    <joint name="joint_3" type="revolute">
        <parent link="link_2" />
        <child link="link_3" />
        <origin rpy="0 0 0" xyz="0.429 0 0" />
        <axis xyz="0 0 1" />
        <!--limit-->
        <limit effort="320" lower="-3.14159265359" upper="3.14159265359" velocity="3.14" />
    </joint>
    <link name="link_3">
        <visual>
            <geometry>
                <mesh filename="package://tmr_description/meshes/tm5-900/visual/tm5-900_arm2.obj" />
            </geometry>
            <material name="none" />
        </visual>
        <collision>
            <geometry>
                <mesh filename="package://tmr_description/meshes/tm5-900/collision/tm5-900_arm2_c.stl" />
            </geometry>
        </collision>
        <inertial>
            <mass value="2.5" />
            <origin rpy="0 0 0" xyz="0.20575 0 -0.0163" />
            <inertia ixx="0.00253125" ixy="0.0" ixz="0.0" iyy="0.0365431624661" iyz="0.0" izz="0.0365431624661" />
        </inertial>
    </link>
    <joint name="joint_4" type="revolute">
        <parent link="link_3" />
        <child link="link_4" />
        <origin rpy="0 0 1.57079632679" xyz="0.4115 0 -0.1223" />
        <axis xyz="0 0 1" />
        <!--limit-->
        <limit effort="80" lower="-3.14159265359" upper="3.14159265359" velocity="3.92" />
    </joint>
    <link name="link_4">
        <visual>
            <geometry>
                <mesh filename="package://tmr_description/meshes/tm5-900/visual/tmr_100w_01.obj" />
            </geometry>
            <material name="none" />
        </visual>
        <collision>
            <geometry>
                <mesh filename="package://tmr_description/meshes/tm5-900/collision/tmr_100w_01_c.stl" />
            </geometry>
        </collision>
        <inertial>
            <mass value="1.45" />
            <origin rpy="0 0 0" xyz="0 0 0" />
            <inertia ixx="0.00247406151038" ixy="0.0" ixz="0.0" iyy="0.001468125" iyz="0.0" izz="0.00247406151038" />
        </inertial>
    </link>
    <joint name="joint_5" type="revolute">
        <parent link="link_4" />
        <child link="link_5" />
        <origin rpy="1.57079632679 0 0" xyz="0 -0.106 0" />
        <axis xyz="0 0 1" />
        <!--limit-->
        <limit effort="80" lower="-3.14159265359" upper="3.14159265359" velocity="3.92" />
    </joint>
    <link name="link_5">
        <visual>
            <geometry>
                <mesh filename="package://tmr_description/meshes/tm5-900/visual/tmr_100w_02.obj" />
            </geometry>
            <material name="none" />
        </visual>
        <collision>
            <geometry>
                <mesh filename="package://tmr_description/meshes/tm5-900/collision/tmr_100w_02_c.stl" />
            </geometry>
        </collision>
        <inertial>
            <mass value="1.45" />
            <origin rpy="0 0 0" xyz="0 0 0" />
            <inertia ixx="0.00247406151038" ixy="0.0" ixz="0.0" iyy="0.001468125" iyz="0.0" izz="0.00247406151038" />
        </inertial>
    </link>
    <joint name="joint_6" type="revolute">
        <parent link="link_5" />
        <child link="link_6" />
        <origin rpy="1.57079632679 0 0" xyz="0 -0.11315 0" />
        <axis xyz="0 0 1" />
        <!--limit-->
        <limit effort="80" lower="-4.71238898038" upper="4.71238898038" velocity="3.92" />
    </joint>
    <link name="link_6">
        <visual>
            <geometry>
                <mesh filename="package://tmr_description/meshes/tm5-900/visual/tmr_ee.obj" />
            </geometry>
            <material name="none" />
        </visual>
        <collision>
            <geometry>
                <mesh filename="package://tmr_description/meshes/tm5-900/collision/tmr_ee_c.stl" />
            </geometry>
        </collision>
        <inertial>
            <mass value="0.4" />
            <origin rpy="0 0 0" xyz="0 0 0" />
            <inertia ixx="0.000322499871" ixy="0.0" ixz="0.0" iyy="0.000322499871" iyz="0.0" izz="0.000405" />
        </inertial>
    </link>
    <link name="base" />
    <joint name="base_fixed_joint" type="fixed">
        <parent link="base" />
        <child link="link_0" />
        <origin rpy="0 0 0" xyz="0 0 0" />
    </joint>
    <link name="flange" />
    <joint name="flange_fixed_joint" type="fixed">
        <parent link="link_6" />
        <child link="flange" />
        <origin rpy="0 0 0" xyz="0 0 0" />
    </joint>
    <!--
LinkDescriptionEnd
/-->
    <link name="world" />
    <joint name="world_joint" type="fixed">
        <parent link="world" />
        <child link="base" />
        <origin rpy="0 0 0" xyz="0 0 0" />
    </joint>
    <transmission name="trans_joint_1">
        <type>transmission_interface/SimpleTransmission</type>
        <joint name="joint_1">
            <hardwareInterface>hardware_interface/EffortJointInterface</hardwareInterface>
        </joint>
        <actuator name="joint_1_motor">
            <hardwareInterface>hardware_interface/EffortJointInterface</hardwareInterface>
            <mechanicalReduction>1</mechanicalReduction>
        </actuator>
    </transmission>
    <transmission name="trans_joint_2">
        <type>transmission_interface/SimpleTransmission</type>
        <joint name="joint_2">
            <hardwareInterface>hardware_interface/EffortJointInterface</hardwareInterface>
        </joint>
        <actuator name="joint_2_motor">
            <hardwareInterface>hardware_interface/EffortJointInterface</hardwareInterface>
            <mechanicalReduction>1</mechanicalReduction>
        </actuator>
    </transmission>
    <transmission name="trans_joint_3">
        <type>transmission_interface/SimpleTransmission</type>
        <joint name="joint_3">
            <hardwareInterface>hardware_interface/EffortJointInterface</hardwareInterface>
        </joint>
        <actuator name="joint_3_motor">
            <hardwareInterface>hardware_interface/EffortJointInterface</hardwareInterface>
            <mechanicalReduction>1</mechanicalReduction>
        </actuator>
    </transmission>
    <transmission name="trans_joint_4">
        <type>transmission_interface/SimpleTransmission</type>
        <joint name="joint_4">
            <hardwareInterface>hardware_interface/EffortJointInterface</hardwareInterface>
        </joint>
        <actuator name="joint_4_motor">
            <hardwareInterface>hardware_interface/EffortJointInterface</hardwareInterface>
            <mechanicalReduction>1</mechanicalReduction>
        </actuator>
    </transmission>
    <transmission name="trans_joint_5">
        <type>transmission_interface/SimpleTransmission</type>
        <joint name="joint_5">
            <hardwareInterface>hardware_interface/EffortJointInterface</hardwareInterface>
        </joint>
        <actuator name="joint_5_motor">
            <hardwareInterface>hardware_interface/EffortJointInterface</hardwareInterface>
            <mechanicalReduction>1</mechanicalReduction>
        </actuator>
    </transmission>
    <transmission name="trans_joint_6">
        <type>transmission_interface/SimpleTransmission</type>
        <joint name="joint_6">
            <hardwareInterface>hardware_interface/EffortJointInterface</hardwareInterface>
        </joint>
        <actuator name="joint_6_motor">
            <hardwareInterface>hardware_interface/EffortJointInterface</hardwareInterface>
            <mechanicalReduction>1</mechanicalReduction>
        </actuator>
    </transmission>
    <gazebo>
        <plugin name="gazebo_ros_control" filename="libgazebo_ros_control.so">
            <robotNamespace>/</robotNamespace>
        </plugin>
    </gazebo>
</robot>
