<sdf version='1.6'>
  <model name='tm5-700'>
    <link name='base'>
      <pose frame=''>0 0 0 0 -0 0</pose>
      <inertial>
        <pose frame=''>0 0 0 0 -0 0</pose>
        <mass>1</mass>
        <inertia>
          <ixx>0.00110833</ixx>
          <ixy>0</ixy>
          <ixz>0</ixz>
          <iyy>0.00110833</iyy>
          <iyz>0</iyz>
          <izz>0.0018</izz>
        </inertia>
      </inertial>
      <collision name='base_fixed_joint_lump__link_0_collision'>
        <pose frame=''>0 0 0 0 -0 0</pose>
        <geometry>
          <mesh>
            <scale>1 1 1</scale>
            <uri>model://tm5-700/meshes/tm5-700/collision/tm5-base_c.stl</uri>
          </mesh>
        </geometry>
        <surface>
          <contact>
            <ode/>
          </contact>
          <friction>
            <ode/>
          </friction>
        </surface>
      </collision>
      <visual name='base_fixed_joint_lump__link_0_visual'>
        <pose frame=''>0 0 0 0 -0 0</pose>
        <geometry>
          <mesh>
            <scale>1 1 1</scale>
            <uri>model://tm5-700/meshes/tm5-700/visual/tm5-base.stl</uri>
          </mesh>
        </geometry>
        <material>
          <script>
            <name>Gazebo/Grey</name>
            <uri>file://media/materials/scripts/gazebo.material</uri>
          </script>
        </material>
      </visual>
      <velocity_decay/>
      <gravity>1</gravity>
      <velocity_decay/>
      <self_collide>1</self_collide>
    </link>
    <joint name='world_joint' type='fixed'>
      <child>base</child>
      <parent>world</parent>
    </joint>
    <link name='link_1'>
      <pose frame=''>0 0 0.1452 0 -0 0</pose>
      <inertial>
        <pose frame=''>0 0 0 0 -0 0</pose>
        <mass>4.032</mass>
        <inertia>
          <ixx>0.00880012</ixx>
          <ixy>0</ixy>
          <ixz>0</ixz>
          <iyy>0.011549</iyy>
          <iyz>0</iyz>
          <izz>0.0119701</izz>
        </inertia>
      </inertial>
      <collision name='link_1_collision'>
        <pose frame=''>0 0 0 0 -0 0</pose>
        <geometry>
          <mesh>
            <scale>1 1 1</scale>
            <uri>model://tm5-700/meshes/tm5-700/collision/tmr_400w_01_c.stl</uri>
          </mesh>
        </geometry>
        <surface>
          <contact>
            <ode/>
          </contact>
          <friction>
            <ode/>
          </friction>
        </surface>
      </collision>
      <visual name='link_1_visual'>
        <pose frame=''>0 0 0 0 -0 0</pose>
        <geometry>
          <mesh>
            <scale>1 1 1</scale>
            <uri>model://tm5-700/meshes/tm5-700/visual/tmr_400w_01.stl</uri>
          </mesh>
        </geometry>
        <material>
          <script>
            <name>Gazebo/Motorway</name>
            <uri>file://media/materials/scripts/gazebo.material</uri>
          </script>
        </material>
      </visual>
      <gravity>1</gravity>
      <velocity_decay/>
      <self_collide>1</self_collide>
    </link>
    <joint name='shoulder_1_joint' type='revolute'>
      <child>link_1</child>
      <parent>base</parent>
      <axis>
        <xyz>0 0 1</xyz>
        <limit>
          <lower>-4.71239</lower>
          <upper>4.71239</upper>
          <effort>157</effort>
          <velocity>3.14159</velocity>
        </limit>
        <dynamics>
          <damping>0</damping>
          <friction>0</friction>
          <spring_reference>0</spring_reference>
          <spring_stiffness>0</spring_stiffness>
        </dynamics>
        <use_parent_model_frame>1</use_parent_model_frame>
      </axis>
    </joint>
    <link name='link_2'>
      <pose frame=''>0 0 0.1452 1.57079 -1.57079 3.14159</pose>
      <inertial>
        <pose frame=''>0 0 0 0 -0 0</pose>
        <mass>8.567</mass>
        <inertia>
          <ixx>0.0235521</ixx>
          <ixy>0</ixy>
          <ixz>0</ixz>
          <iyy>0.198252</iyy>
          <iyz>0</iyz>
          <izz>0.204593</izz>
        </inertia>
      </inertial>
      <collision name='link_2_collision'>
        <pose frame=''>0 0 0 0 -0 0</pose>
        <geometry>
          <mesh>
            <scale>1 1 1</scale>
            <uri>model://tm5-700/meshes/tm5-700/collision/tm5-700_arm1_c.stl</uri>
          </mesh>
        </geometry>
        <surface>
          <contact>
            <ode/>
          </contact>
          <friction>
            <ode/>
          </friction>
        </surface>
      </collision>
      <visual name='link_2_visual'>
        <pose frame=''>0 0 0 0 -0 0</pose>
        <geometry>
          <mesh>
            <scale>1 1 1</scale>
            <uri>model://tm5-700/meshes/tm5-700/visual/tm5-700_arm1.stl</uri>
          </mesh>
        </geometry>
        <material>
          <script>
            <name>Gazebo/Motorway</name>
            <uri>file://media/materials/scripts/gazebo.material</uri>
          </script>
        </material>
      </visual>
      <gravity>1</gravity>
      <velocity_decay/>
      <self_collide>1</self_collide>
    </link>
    <joint name='shoulder_2_joint' type='revolute'>
      <child>link_2</child>
      <parent>link_1</parent>
      <axis>
        <xyz>-0 1 0</xyz>
        <limit>
          <lower>-3.14159</lower>
          <upper>3.14159</upper>
          <effort>157</effort>
          <velocity>3.14159</velocity>
        </limit>
        <dynamics>
          <damping>0</damping>
          <friction>0</friction>
          <spring_reference>0</spring_reference>
          <spring_stiffness>0</spring_stiffness>
        </dynamics>
        <use_parent_model_frame>1</use_parent_model_frame>
      </axis>
    </joint>
    <link name='link_3'>
      <pose frame=''>0 0 0.4742 1.57079 -1.57079 3.14159</pose>
      <inertial>
        <pose frame=''>0 0 0 0 -0 0</pose>
        <mass>2.273</mass>
        <inertia>
          <ixx>0.00338018</ixx>
          <ixy>0</ixy>
          <ixz>0</ixz>
          <iyy>0.0338291</iyy>
          <iyz>0</iyz>
          <izz>0.0343282</izz>
        </inertia>
      </inertial>
      <collision name='link_3_collision'>
        <pose frame=''>0 0 0 0 -0 0</pose>
        <geometry>
          <mesh>
            <scale>1 1 1</scale>
            <uri>model://tm5-700/meshes/tm5-700/collision/tm5-700_arm2_c.stl</uri>
          </mesh>
        </geometry>
        <surface>
          <contact>
            <ode/>
          </contact>
          <friction>
            <ode/>
          </friction>
        </surface>
      </collision>
      <visual name='link_3_visual'>
        <pose frame=''>0 0 0 0 -0 0</pose>
        <geometry>
          <mesh>
            <scale>1 1 1</scale>
            <uri>model://tm5-700/meshes/tm5-700/visual/tm5-700_arm2.stl</uri>
          </mesh>
        </geometry>
        <material>
          <script>
            <name>Gazebo/Motorway</name>
            <uri>file://media/materials/scripts/gazebo.material</uri>
          </script>
        </material>
      </visual>
      <gravity>1</gravity>
      <velocity_decay/>
      <self_collide>1</self_collide>
    </link>
    <joint name='elbow_joint' type='revolute'>
      <child>link_3</child>
      <parent>link_2</parent>
      <axis>
        <xyz>-0 1 0</xyz>
        <limit>
          <lower>-2.70526</lower>
          <upper>2.70526</upper>
          <effort>157</effort>
          <velocity>3.14159</velocity>
        </limit>
        <dynamics>
          <damping>0</damping>
          <friction>0</friction>
          <spring_reference>0</spring_reference>
          <spring_stiffness>0</spring_stiffness>
        </dynamics>
        <use_parent_model_frame>1</use_parent_model_frame>
      </axis>
    </joint>
    <link name='link_4'>
      <pose frame=''>0 -0.1223 0.7857 -1.5708 -0 0</pose>
      <inertial>
        <pose frame=''>0 0 0 0 -0 0</pose>
        <mass>1.576</mass>
        <inertia>
          <ixx>0.00205841</ixx>
          <ixy>0</ixy>
          <ixz>0</ixz>
          <iyy>0.00256308</iyy>
          <iyz>0</iyz>
          <izz>0.00264321</izz>
        </inertia>
      </inertial>
      <collision name='link_4_collision'>
        <pose frame=''>0 0 0 0 -0 0</pose>
        <geometry>
          <mesh>
            <scale>1 1 1</scale>
            <uri>model://tm5-700/meshes/tm5-700/collision/tmr_100w_01_c.stl</uri>
          </mesh>
        </geometry>
        <surface>
          <contact>
            <ode/>
          </contact>
          <friction>
            <ode/>
          </friction>
        </surface>
      </collision>
      <visual name='link_4_visual'>
        <pose frame=''>0 0 0 0 -0 0</pose>
        <geometry>
          <mesh>
            <scale>1 1 1</scale>
            <uri>model://tm5-700/meshes/tm5-700/visual/tmr_100w_01.stl</uri>
          </mesh>
        </geometry>
        <material>
          <script>
            <name>Gazebo/Motorway</name>
            <uri>file://media/materials/scripts/gazebo.material</uri>
          </script>
        </material>
      </visual>
      <gravity>1</gravity>
      <velocity_decay/>
      <self_collide>1</self_collide>
    </link>
    <joint name='wrist_1_joint' type='revolute'>
      <child>link_4</child>
      <parent>link_3</parent>
      <axis>
        <xyz>-0 1 0</xyz>
        <limit>
          <lower>-3.14159</lower>
          <upper>3.14159</upper>
          <effort>43</effort>
          <velocity>3.92699</velocity>
        </limit>
        <dynamics>
          <damping>0</damping>
          <friction>0</friction>
          <spring_reference>0</spring_reference>
          <spring_stiffness>0</spring_stiffness>
        </dynamics>
        <use_parent_model_frame>1</use_parent_model_frame>
      </axis>
    </joint>
    <link name='link_5'>
      <pose frame=''>0 -0.1223 0.8917 -0 -0 0</pose>
      <inertial>
        <pose frame=''>0 0 0 0 -0 0</pose>
        <mass>1.576</mass>
        <inertia>
          <ixx>0.00205841</ixx>
          <ixy>0</ixy>
          <ixz>0</ixz>
          <iyy>0.00256308</iyy>
          <iyz>0</iyz>
          <izz>0.00264321</izz>
        </inertia>
      </inertial>
      <collision name='link_5_collision'>
        <pose frame=''>0 0 0 0 -0 0</pose>
        <geometry>
          <mesh>
            <scale>1 1 1</scale>
            <uri>model://tm5-700/meshes/tm5-700/collision/tmr_100w_02_c.stl</uri>
          </mesh>
        </geometry>
        <surface>
          <contact>
            <ode/>
          </contact>
          <friction>
            <ode/>
          </friction>
        </surface>
      </collision>
      <visual name='link_5_visual'>
        <pose frame=''>0 0 0 0 -0 0</pose>
        <geometry>
          <mesh>
            <scale>1 1 1</scale>
            <uri>model://tm5-700/meshes/tm5-700/visual/tmr_100w_02.stl</uri>
          </mesh>
        </geometry>
        <material>
          <script>
            <name>Gazebo/Motorway</name>
            <uri>file://media/materials/scripts/gazebo.material</uri>
          </script>
        </material>
      </visual>
      <gravity>1</gravity>
      <velocity_decay/>
      <self_collide>1</self_collide>
    </link>
    <joint name='wrist_2_joint' type='revolute'>
      <child>link_5</child>
      <parent>link_4</parent>
      <axis>
        <xyz>-0 0 1</xyz>
        <limit>
          <lower>-3.14159</lower>
          <upper>3.14159</upper>
          <effort>43</effort>
          <velocity>3.92699</velocity>
        </limit>
        <dynamics>
          <damping>0</damping>
          <friction>0</friction>
          <spring_reference>0</spring_reference>
          <spring_stiffness>0</spring_stiffness>
        </dynamics>
        <use_parent_model_frame>1</use_parent_model_frame>
      </axis>
    </joint>
    <link name='link_6'>
      <pose frame=''>0 -0.23545 0.8917 1.5708 -0 0</pose>
      <inertial>
        <pose frame=''>0 0 0 0 -0 0</pose>
        <mass>0.65</mass>
        <inertia>
          <ixx>0.000774544</ixx>
          <ixy>0</ixy>
          <ixz>0</ixz>
          <iyy>0.00138381</iyy>
          <iyz>0</iyz>
          <izz>0.0015595</izz>
        </inertia>
      </inertial>
      <collision name='link_6_collision'>
        <pose frame=''>0 0 0 0 -0 0</pose>
        <geometry>
          <mesh>
            <scale>1 1 1</scale>
            <uri>model://tm5-700/meshes/tm5-700/collision/tmr_ee_c.stl</uri>
          </mesh>
        </geometry>
        <surface>
          <contact>
            <ode/>
          </contact>
          <friction>
            <ode/>
          </friction>
        </surface>
      </collision>
      <visual name='link_6_visual'>
        <pose frame=''>0 0 0 0 -0 0</pose>
        <geometry>
          <mesh>
            <scale>1 1 1</scale>
            <uri>model://tm5-700/meshes/tm5-700/visual/tmr_ee.stl</uri>
          </mesh>
        </geometry>
        <material>
          <script>
            <name>Gazebo/Grey</name>
            <uri>file://media/materials/scripts/gazebo.material</uri>
          </script>
        </material>
      </visual>
      <gravity>1</gravity>
      <velocity_decay/>
      <self_collide>1</self_collide>
    </link>
    <joint name='wrist_3_joint' type='revolute'>
      <child>link_6</child>
      <parent>link_5</parent>
      <axis>
        <xyz>0 -1 1e-06</xyz>
        <limit>
          <lower>-4.71239</lower>
          <upper>4.71239</upper>
          <effort>43</effort>
          <velocity>3.92699</velocity>
        </limit>
        <dynamics>
          <damping>0</damping>
          <friction>0</friction>
          <spring_reference>0</spring_reference>
          <spring_stiffness>0</spring_stiffness>
        </dynamics>
        <use_parent_model_frame>1</use_parent_model_frame>
      </axis>
    </joint>
    <static>0</static>
    <plugin name='gazebo_ros_control' filename='libgazebo_ros_control.so'>
      <robotNamespace>/</robotNamespace>
      <robotSimType>gazebo_ros_control/DefaultRobotHWSim</robotSimType>
    </plugin>
  </model>
</sdf>
